Workbook

Sheet 总览
A1: Steam 视觉小说 2020–2025｜扩展总览 | R1: 分类 | S1: 游戏数 | U1: 年份 | V1: 全部游戏
R2: 全年龄 | S2: =COUNTIF(游戏总表!$R$2:$R$4661,AF2) -> 0 | U2: =年度统计!A2 -> 2020 | V2: =年度统计!B2 -> 498
A3: 原始交集名单 + 仅由 VNDB 补充的完整游戏；评论热度与成人内容分类规则详见“参数与口径” | R3: 非全年龄 | S3: =COUNTIF(游戏总表!$R$2:$R$4661,AF3) -> 0 | U3: =年度统计!A3 -> 2021 | V3: =年度统计!B3 -> 590
R4: 未知 | S4: =COUNTIF(游戏总表!$R$2:$R$4661,AF4) -> 0 | U4: =年度统计!A4 -> 2022 | V4: =年度统计!B4 -> 758
A5: 纳入统计的游戏总数 | F5: 新增：仅由 VNDB 补充的完整游戏 | K5: 已取得估算销量的游戏 | U5: =年度统计!A5 -> 2023 | V5: =年度统计!B5 -> 814
A6: =COUNTA(游戏总表!$A$2:$A$4661) -> 4660 | F6: =COUNTIF(游戏总表!$Z$2:$Z$4661,"VNDB_ONLY_COMPLETE_INCREMENT") -> 1820 | K6: =COUNT(游戏总表!$I$2:$I$4661) -> 4259 | U6: =年度统计!A6 -> 2024 | V6: =年度统计!B6 -> 992
U7: =年度统计!A7 -> 2025 | V7: =年度统计!B7 -> 1008
A11: 高热度游戏（Steam 评论数>198） | F11: 全年龄游戏（无色情内容标记） | K11: 非全年龄游戏（含色情内容标记）
A12: =COUNTIF(游戏总表!$K$2:$K$4661,">198") -> 934 | F12: =COUNTIF(游戏总表!$R$2:$R$4661,"全年龄") -> 3336 | K12: =COUNTIF(游戏总表!$R$2:$R$4661,"非全年龄") -> 1324

Sheet 参数与口径
A1: 参数、分类规则与数据来源
A4: 参数 | B4: 数值 / 说明
A5: 评论热度阈值 | B5: 198
A6: 阈值以下实际占比 | B6: 0.79957082
A7: 统计截止日 | B7: 46242
A8: 新增名单选择 | B8: 只纳入原名单之外、仅由 VNDB 找到且发行类型为“完整游戏”的记录（技术值：VNDB_ONLY；vndb_rtypes=complete）
A9: 全年龄游戏 | B9: 所有关联发行版本中都没有色情内容标记，并且至少一个版本明确标记为不含色情内容（技术字段：has_ero=false）
A10: 非全年龄游戏 | B10: 任一关联发行版本明确标记为包含色情内容（技术字段：has_ero=true）
A11: 年龄分级（minage） | B11: 只记录年龄门槛，例如 18+；它不能单独证明游戏包含色情内容
A12: 估算累计销量（copiesSold） | B12: Gamalytic 对截至采集日累计售出份数的估算，不是官方销量，也不是发行当月销量
A13: 上市时长 | B13: 从发行日到 2026-08-08 的月数
A15: 数据源 | B15: URL
A16: VNDB Release API | B16: https://api.vndb.org/kana
A17: Steam 官方评论接口说明 | B17: https://partner.steamgames.com/doc/store/getreviews
A18: Gamalytic API | B18: https://api.gamalytic.com/reference/
A20: 英文字段名 | B20: 中文名称 | C20: 给非技术人员的解释 | D20: 数据来源 / 注意事项
A21: steam_appid | B21: Steam 应用编号 | C21: Steam 为每个商店应用分配的唯一数字编号，用于准确识别游戏。 | D21: Steam；同名游戏也可以用该编号区分。
A22: name | B22: 游戏名称 | C22: Steam 商店中显示的游戏名称。 | D22: Steam 商店。
A23: steam_release_date | B23: Steam 发行日期 | C23: 游戏在 Steam 上正式发行的日期。 | D23: Steam；格式为年-月-日。
A24: release_month | B24: 发行月份 | C24: 把发行日期整理到月份，便于统计每月发行数量。 | D24: 根据 Steam 发行日期计算；格式为年-月。
A25: release_year | B25: 发行年份 | C25: 把发行日期整理到年份，便于进行年度比较。 | D25: 根据 Steam 发行日期计算。
A26: months_since_release | B26: 上市时长（月） | C26: 从 Steam 发行日到统计截止日经历的月数。 | D26: 计算值；截止日为 2026-08-08。
A27: store_url | B27: Steam 商店链接 | C27: 打开该游戏 Steam 商店页面的网址。 | D27: Steam。
A28: vndb_url | B28: VNDB 作品链接 | C28: 打开该游戏对应 VNDB 视觉小说条目的网址。 | D28: VNDB；一个 Steam 游戏可能关联多个 VNDB 记录，此处提供主要链接。
A29: copies_sold | B29: 估算累计销量 | C29: Gamalytic 估算该游戏截至采集日累计售出的份数。 | D29: Gamalytic 估算值，不是 Steam 官方销量；缺失时留空。
A30: gamalytic_status | B30: 销量取数状态 | C30: 说明是否成功从 Gamalytic 获得估算销量。 | D30: FOUND=已取得；NOT_FOUND 等值表示未取得。
A31: steam_review_count | B31: Steam 评论总数 | C31: Steam 商店中该游戏收到的用户评论总数。 | D31: Steam 官方评论接口；包含所选语言范围内的评论。
... A54: copies_sold_fetched_at | B54: 销量估算采集时间 | C54: 取得 Gamalytic 估算销量的时间。 | D54: 通常为带时区的时间戳；便于日后更新和核对。

Sheet 游戏总表
A1: steam_appid | B1: name | C1: steam_release_date | D1: release_month | E1: release_year | F1: months_since_release | G1: store_url | H1: vndb_url | I1: copies_sold | J1: gamalytic_status | K1: steam_review_count | L1: steam_review_positive | M1: steam_review_negative | N1: steam_review_positive_rate | O1: steam_review_score_desc | P1: steam_review_status | Q1: review_heat_group | R1: all_ages_status | S1: is_all_ages | T1: has_ero_any | U1: sexual_content_basis | V1: vndb_minage_values | W1: vndb_has_ero_values | X1: vndb_uncensored_values | Y1: sexual_content_conflict | Z1: expanded_source | AA1: in_steam_visual_novel_tag | AB1: vndb_ids | AC1: vndb_release_ids | AD1: vndb_rtypes | AE1: vndb_official | AF1: price_text | AG1: is_free | AH1: copies_sold_fetched_at
A2: 1205160 | B2: Decadent Thinking | C2: 43831 | D2: 2020-01 | E2: 2020 | F2: 79.21 | G2: https://store.steampowered.com/app/1205160/ | H2: https://vndb.org/v27532 | I2: 277 | J2: FOUND | K2: 12 | L2: 9 | M2: 3 | N2: 0.75 | O2: Mostly Positive | P2: FOUND | Q2: 低热度（≤198） | R2: 全年龄 | S2: TRUE | T2: FALSE | U2: has_ero=false | W2: FALSE | Y2: FALSE | Z2: ORIGINAL_INTERSECTION | AA2: TRUE | AB2: v27532 | AC2: r79683 | AD2: complete | AE2: TRUE | AF2: $14.99 | AG2: FALSE | AH2: 46242.565
A3: 1168470 | B3: 千面 Melancholy Love | C3: 43832 | D3: 2020-01 | E3: 2020 | F3: 79.18 | G3: https://store.steampowered.com/app/1168470/ | H3: https://vndb.org/v27565 | I3: 26569 | J3: FOUND | K3: 2234 | L3: 2114 | M3: 120 | N3: 0.94628469 | O3: Very Positive | P3: FOUND | Q3: 高热度（>198） | R3: 全年龄 | S3: TRUE | T3: FALSE | U3: has_ero=false | W3: FALSE | Y3: FALSE | Z3: ORIGINAL_INTERSECTION | AA3: TRUE | AB3: v27565 | AC3: r68714 | AD3: complete | AE3: TRUE | AF3: $4.99 | AG3: FALSE | AH3: 46242.565
A4: 1049100 | B4: 泡沫冬景 | C4: 43832 | D4: 2020-01 | E4: 2020 | F4: 79.18 | G4: https://store.steampowered.com/app/1049100/ | H4: https://vndb.org/v24208 | I4: 90198 | J4: FOUND | K4: 4505 | L4: 4297 | M4: 208 | N4: 0.95382908 | O4: Overwhelmingly Positive | P4: FOUND | Q4: 高热度（>198） | R4: 全年龄 | S4: TRUE | T4: FALSE | U4: has_ero=false | W4: FALSE | Y4: FALSE | Z4: ORIGINAL_INTERSECTION | AA4: TRUE | AB4: v24208 | AC4: r81838 | AD4: complete | AE4: TRUE | AF4: $14.99 | AG4: FALSE | AH4: 46242.565
A5: 590800 | B5: Rainbow Dreams | C5: 43833 | D5: 2020-01 | E5: 2020 | F5: 79.15 | G5: https://store.steampowered.com/app/590800/ | H5: https://vndb.org/v20128 | I5: 118 | J5: FOUND | K5: 7 | L5: 5 | M5: 2 | N5: 0.71428571 | O5: 7 user reviews | P5: FOUND | Q5: 低热度（≤198） | R5: 全年龄 | S5: TRUE | T5: FALSE | U5: has_ero=false | W5: FALSE | Y5: FALSE | Z5: ORIGINAL_INTERSECTION | AA5: TRUE | AB5: v20128 | AC5: r51184 | AD5: complete | AE5: TRUE | AF5: $9.99 | AG5: FALSE | AH5: 46242.565
A6: 1130900 | B6: 黎明霞光 | C6: 43840 | D6: 2020-01 | E6: 2020 | F6: 78.92 | G6: https://store.steampowered.com/app/1130900/ | H6: https://vndb.org/v27663 | I6: 140 | J6: FOUND | K6: 11 | L6: 7 | M6: 4 | N6: 0.63636364 | O6: Mixed | P6: FOUND | Q6: 低热度（≤198） | R6: 全年龄 | S6: TRUE | T6: FALSE | U6: has_ero=false | W6: FALSE | Y6: FALSE | Z6: ORIGINAL_INTERSECTION | AA6: TRUE | AB6: v27663 | AC6: r68896 | AD6: complete | AE6: TRUE | AF6: $2.99 | AG6: FALSE | AH6: 46242.565
A7: 1216080 | B7: 坦率的小红帽和爱说谎的狼 | C7: 43843 | D7: 2020-01 | E7: 2020 | F7: 78.82 | G7: https://store.steampowered.com/app/1216080/ | H7: https://vndb.org/v26215 | I7: 76478 | J7: FOUND | K7: 1132 | L7: 1112 | M7: 20 | N7: 0.98233216 | O7: Overwhelmingly Positive | P7: FOUND | Q7: 高热度（>198） | R7: 全年龄 | S7: TRUE | T7: FALSE | U7: has_ero=false | W7: FALSE | Y7: FALSE | Z7: ORIGINAL_INTERSECTION | AA7: TRUE | AB7: v26215 | AC7: r68929 | AD7: complete | AE7: TRUE | AF7: Free | AG7: TRUE | AH7: 46242.565
A8: 1071350 | B8: Little One - A Visual Novel | C8: 43844 | D8: 2020-01 | E8: 2020 | F8: 78.78 | G8: https://store.steampowered.com/app/1071350/ | H8: https://vndb.org/v24659 | I8: 952 | J8: FOUND | K8: 28 | L8: 21 | M8: 7 | N8: 0.75 | O8: Mostly Positive | P8: FOUND | Q8: 低热度（≤198） | R8: 全年龄 | S8: TRUE | T8: FALSE | U8: has_ero=false | W8: FALSE | Y8: FALSE | Z8: ORIGINAL_INTERSECTION | AA8: TRUE | AB8: v24659 | AC8: r68937 | AD8: complete | AE8: TRUE | AF8: $9.99 | AG8: FALSE | AH8: 46242.565
A9: 1217390 | B9: Some Some Convenience Store | C9: 43844 | D9: 2020-01 | E9: 2020 | F9: 78.78 | G9: https://store.steampowered.com/app/1217390/ | H9: https://vndb.org/v27704 | I9: 70930 | J9: FOUND | K9: 3101 | L9: 2975 | M9: 126 | N9: 0.95936795 | O9: Overwhelmingly Positive | P9: FOUND | Q9: 高热度（>198） | R9: 全年龄 | S9: TRUE | T9: FALSE | U9: VNDB minage=15; has_ero=false | V9: 15 | W9: FALSE | Y9: FALSE | Z9: ORIGINAL_INTERSECTION | AA9: TRUE | AB9: v27704 | AC9: r122970 | AD9: complete | AE9: TRUE | AF9: $14.99 | AG9: FALSE | AH9: 46242.565
A10: 1179100 | B10: Oppaidius Tropical Cruise! | C10: 43846 | D10: 2020-01 | E10: 2020 | F10: 78.72 | G10: https://store.steampowered.com/app/1179100/ | H10: https://vndb.org/v26772 | I10: 11169 | J10: FOUND | K10: 146 | L10: 133 | M10: 13 | N10: 0.9109589 | O10: Very Positive | P10: FOUND | Q10: 低热度（≤198） | R10: 全年龄 | S10: TRUE | T10: FALSE | U10: has_ero=false | W10: FALSE | Y10: FALSE | Z10: VNDB_ONLY_COMPLETE_INCREMENT | AA10: FALSE | AB10: v26772 | AC10: r66996 | AD10: complete | AE10: TRUE | AG10: FALSE | AH10: 46242.565
A11: 1148930 | B11: Chuusotsu! 1.5th Graduation: The Moving Castle | C11: 43847 | D11: 2020-01 | E11: 2020 | F11: 78.69 | G11: https://store.steampowered.com/app/1148930/ | H11: https://vndb.org/v21410 | I11: 368 | J11: FOUND | K11: 23 | L11: 22 | M11: 1 | N11: 0.95652174 | O11: Positive | P11: FOUND | Q11: 低热度（≤198） | R11: 全年龄 | S11: TRUE | T11: FALSE | U11: has_ero=false | W11: FALSE | Y11: FALSE | Z11: ORIGINAL_INTERSECTION | AA11: TRUE | AB11: v21410 | AC11: r52277 | AD11: complete | AE11: TRUE | AF11: $9.99 | AG11: FALSE | AH11: 46242.565
A12: 1198630 | B12: Customer Cums First! | C12: 43847 | D12: 2020-01 | E12: 2020 | F12: 78.69 | G12: https://store.steampowered.com/app/1198630/ | H12: https://vndb.org/v13956 | I12: 1340 | J12: FOUND | K12: 34 | L12: 23 | M12: 11 | N12: 0.67647059 | O12: Mixed | P12: FOUND | Q12: 低热度（≤198） | R12: 非全年龄 | S12: FALSE | T12: TRUE | U12: VNDB minage=18; has_ero=true; uncensored=false | V12: 18 | W12: TRUE | X12: FALSE | Y12: FALSE | Z12: VNDB_ONLY_COMPLETE_INCREMENT | AA12: FALSE | AB12: v13956 | AC12: r68719;r86147 | AD12: complete | AE12: TRUE | AG12: FALSE | AH12: 46242.565
A13: 1215120 | B13: DeeperRed2028-WeAreEscape- | C13: 43847 | D13: 2020-01 | E13: 2020 | F13: 78.69 | G13: https://store.steampowered.com/app/1215120/ | H13: https://vndb.org/v27703 | I13: 140 | J13: FOUND | K13: 10 | L13: 10 | M13: 0 | N13: 1 | O13: Positive | P13: FOUND | Q13: 低热度（≤198） | R13: 全年龄 | S13: TRUE | T13: FALSE | U13: has_ero=false | W13: FALSE | Y13: FALSE | Z13: ORIGINAL_INTERSECTION | AA13: TRUE | AB13: v27703 | AC13: r68990 | AD13: complete | AE13: TRUE | AF13: $1.99 | AG13: FALSE | AH13: 46242.565
A14: 1215680 | B14: LVN Fake News - Adult Patch | C14: 43847 | D14: 2020-01 | E14: 2020 | F14: 78.69 | G14: https://store.steampowered.com/app/1215680/ | H14: https://vndb.org/v24006 | J14: NOT_FOUND | K14: 1 | L14: 1 | M14: 0 | N14: 1 | O14: 1 user reviews | P14: FOUND | Q14: 低热度（≤198） | R14: 非全年龄 | S14: FALSE | T14: TRUE | U14: VNDB minage=18; has_ero=true; uncensored=false | V14: 18 | W14: TRUE | X14: FALSE | Y14: FALSE | Z14: VNDB_ONLY_COMPLETE_INCREMENT | AA14: FALSE | AB14: v24006 | AC14: r68988 | AD14: complete | AE14: TRUE | AG14: FALSE | AH14: 46242.565
A15: 1118000 | B15: Revenant March | C15: 43847 | D15: 2020-01 | E15: 2020 | F15: 78.69 | G15: https://store.steampowered.com/app/1118000/ | H15: https://vndb.org/v27702 | I15: 518 | J15: FOUND | K15: 22 | L15: 20 | M15: 2 | N15: 0.90909091 | O15: Positive | P15: FOUND | Q15: 低热度（≤198） | R15: 全年龄 | S15: TRUE | T15: FALSE | U15: has_ero=false | W15: FALSE | Y15: FALSE | Z15: ORIGINAL_INTERSECTION | AA15: TRUE | AB15: v27702 | AC15: r68989 | AD15: complete | AE15: TRUE | AF15: $4.99 | AG15: FALSE | AH15: 46242.565
A16: 1017880 | B16: The Dark Side | C16: 43850 | D16: 2020-01 | E16: 2020 | F16: 78.59 | G16: https://store.steampowered.com/app/1017880/ | H16: https://vndb.org/v27644 | I16: 286 | J16: FOUND | K16: 13 | L16: 8 | M16: 5 | N16: 0.61538462 | O16: Mixed | P16: FOUND | Q16: 低热度（≤198） | R16: 全年龄 | S16: TRUE | T16: FALSE | U16: VNDB minage=10; has_ero=false | V16: 10 | W16: FALSE | Y16: FALSE | Z16: ORIGINAL_INTERSECTION | AA16: TRUE | AB16: v27644 | AC16: r68834 | AD16: complete | AE16: TRUE | AF16: $0.99 | AG16: FALSE | AH16: 46242.565
A17: 1193330 | B17: Together - A Wish No One Remembers | C17: 43850 | D17: 2020-01 | E17: 2020 | F17: 78.59 | G17: https://store.steampowered.com/app/1193330/ | H17: https://vndb.org/v27735 | I17: 165 | J17: FOUND | K17: 11 | L17: 11 | M17: 0 | N17: 1 | O17: Positive | P17: FOUND | Q17: 低热度（≤198） | R17: 全年龄 | S17: TRUE | T17: FALSE | U17: VNDB minage=0; has_ero=false | V17: 0 | W17: FALSE | Y17: FALSE | Z17: ORIGINAL_INTERSECTION | AA17: TRUE | AB17: v27735 | AC17: r69056;r74329 | AD17: complete;trial | AE17: TRUE | AF17: $1.99 | AG17: FALSE | AH17: 46242.565
A18: 1149550 | B18: Utawarerumono: Mask of Deception | C18: 43853 | D18: 2020-01 | E18: 2020 | F18: 78.49 | G18: https://store.steampowered.com/app/1149550/ | H18: https://vndb.org/v7721 | I18: 52299 | J18: FOUND | K18: 1377 | L18: 1276 | M18: 101 | N18: 0.92665214 | O18: Very Positive | P18: FOUND | Q18: 高热度（>198） | R18: 全年龄 | S18: TRUE | T18: FALSE | U18: has_ero=false | W18: FALSE | Y18: FALSE | Z18: ORIGINAL_INTERSECTION | AA18: TRUE | AB18: v7721 | AC18: r68816 | AD18: complete | AE18: TRUE | AF18: $39.99 | AG18: FALSE | AH18: 46242.565
A19: 1151440 | B19: Utawarerumono: Mask of Truth | C19: 43853 | D19: 2020-01 | E19: 2020 | F19: 78.49 | G19: https://store.steampowered.com/app/1151440/ | H19: https://vndb.org/v18717 | I19: 35712 | J19: FOUND | K19: 1508 | L19: 1453 | M19: 55 | N19: 0.96352785 | O19: Overwhelmingly Positive | P19: FOUND | Q19: 高热度（>198） | R19: 全年龄 | S19: TRUE | T19: FALSE | U19: has_ero=false | W19: FALSE | Y19: FALSE | Z19: ORIGINAL_INTERSECTION | AA19: TRUE | AB19: v18717 | AC19: r68817 | AD19: complete | AE19: TRUE | AF19: $39.99 | AG19: FALSE | AH19: 46242.565
A20: 1123190 | B20: 育种村 | C20: 43854 | D20: 2020-01 | E20: 2020 | F20: 78.46 | G20: https://store.steampowered.com/app/1123190/ | H20: https://vndb.org/v23154 | I20: 3905 | J20: FOUND | K20: 87 | L20: 62 | M20: 25 | N20: 0.71264368 | O20: Mostly Positive | P20: FOUND | Q20: 低热度（≤198） | R20: 非全年龄 | S20: FALSE | T20: TRUE | U20: VNDB minage=18; has_ero=true; uncensored=false | V20: 18 | W20: TRUE | X20: FALSE | Y20: FALSE | Z20: VNDB_ONLY_COMPLETE_INCREMENT | AA20: FALSE | AB20: v23154 | AC20: r69113 | AD20: complete | AE20: TRUE | AG20: FALSE | AH20: 46242.565
A21: 1180360 | B21: Two Love | C21: 43855 | D21: 2020-01 | E21: 2020 | F21: 78.42 | G21: https://store.steampowered.com/app/1180360/ | H21: https://vndb.org/v27760 | I21: 396 | J21: FOUND | K21: 11 | L21: 10 | M21: 1 | N21: 0.90909091 | O21: Positive | P21: FOUND | Q21: 低热度（≤198） | R21: 全年龄 | S21: TRUE | T21: FALSE | U21: has_ero=false | W21: FALSE | Y21: FALSE | Z21: ORIGINAL_INTERSECTION | AA21: TRUE | AB21: v27760 | AC21: r69123 | AD21: complete | AE21: TRUE | AF21: Free | AG21: TRUE | AH21: 46242.565
A22: 1165920 | B22: Lives so Sweet | C22: 43856 | D22: 2020-01 | E22: 2020 | F22: 78.39 | G22: https://store.steampowered.com/app/1165920/ | H22: https://vndb.org/v26393 | I22: 662 | J22: FOUND | K22: 20 | L22: 14 | M22: 6 | N22: 0.7 | O22: Mostly Positive | P22: FOUND | Q22: 低热度（≤198） | R22: 非全年龄 | S22: FALSE | T22: TRUE | U22: VNDB minage=18; has_ero=true; uncensored=true | V22: 18 | W22: TRUE | X22: TRUE | Y22: FALSE | Z22: VNDB_ONLY_COMPLETE_INCREMENT | AA22: FALSE | AB22: v26393 | AC22: r65652 | AD22: complete | AE22: TRUE | AG22: FALSE | AH22: 46242.565
A23: 914800 | B23: Coffee Talk | C23: 43859 | D23: 2020-01 | E23: 2020 | F23: 78.29 | G23: https://store.steampowered.com/app/914800/ | H23: https://vndb.org/v23634 | I23: 400135 | J23: FOUND | K23: 12500 | L23: 11837 | M23: 663 | N23: 0.94696 | O23: Very Positive | P23: FOUND | Q23: 高热度（>198） | R23: 全年龄 | S23: TRUE | T23: FALSE | U23: has_ero=false | W23: FALSE | Y23: FALSE | Z23: ORIGINAL_INTERSECTION | AA23: TRUE | AB23: v23634 | AC23: r69236 | AD23: complete | AE23: TRUE | AF23: -50% | AG23: FALSE | AH23: 46242.565
A24: 2205000 | B24: Talk To Me | C24: 43859 | D24: 2020-01 | E24: 2020 | F24: 78.29 | G24: https://store.steampowered.com/app/2205000/ | H24: https://vndb.org/v19449 | J24: NOT_FOUND | K24: 0 | L24: 0 | M24: 0 | O24: No user reviews | P24: FOUND | Q24: 低热度（≤198） | R24: 非全年龄 | S24: FALSE | T24: TRUE | U24: VNDB minage=17; has_ero=true; uncensored=true | V24: 17 | W24: TRUE | X24: TRUE | Y24: FALSE | Z24: VNDB_ONLY_COMPLETE_INCREMENT | AA24: FALSE | AB24: v19449 | AC24: r46391 | AD24: complete | AE24: TRUE | AG24: FALSE | AH24: 46242.565
A25: 1011190 | B25: SIMULACRA 2 | C25: 43860 | D25: 2020-01 | E25: 2020 | F25: 78.26 | G25: https://store.steampowered.com/app/1011190/ | H25: https://vndb.org/v57038 | I25: 56838 | J25: FOUND | K25: 1686 | L25: 1461 | M25: 225 | N25: 0.86654804 | O25: Very Positive | P25: FOUND | Q25: 高热度（>198） | R25: 全年龄 | S25: TRUE | T25: FALSE | U25: VNDB minage=12; has_ero=false | V25: 12 | W25: FALSE | Y25: FALSE | Z25: ORIGINAL_INTERSECTION | AA25: TRUE | AB25: v57038 | AC25: r137195 | AD25: complete | AE25: TRUE | AF25: $7.99 | AG25: FALSE | AH25: 46242.565
A26: 1087800 | B26: Arranged | C26: 43861 | D26: 2020-01 | E26: 2020 | F26: 78.23 | G26: https://store.steampowered.com/app/1087800/ | H26: https://vndb.org/v27834 | I26: 522 | J26: FOUND | K26: 17 | L26: 14 | M26: 3 | N26: 0.82352941 | O26: Positive | P26: FOUND | Q26: 低热度（≤198） | R26: 全年龄 | S26: TRUE | T26: FALSE | U26: has_ero=false | W26: FALSE | Y26: FALSE | Z26: ORIGINAL_INTERSECTION | AA26: TRUE | AB26: v27834 | AC26: r69316 | AD26: complete | AE26: TRUE | AF26: $0.99 | AG26: FALSE | AH26: 46242.565
A27: 1106950 | B27: Furries & Scalies: Friendswood | C27: 43861 | D27: 2020-01 | E27: 2020 | F27: 78.23 | G27: https://store.steampowered.com/app/1106950/ | H27: https://vndb.org/v27836 | I27: 1 | J27: FOUND | K27: 1 | L27: 1 | M27: 0 | N27: 1 | O27: 1 user reviews | P27: FOUND | Q27: 低热度（≤198） | R27: 全年龄 | S27: TRUE | T27: FALSE | U27: has_ero=false | W27: FALSE | Y27: FALSE | Z27: ORIGINAL_INTERSECTION | AA27: TRUE | AB27: v27836 | AC27: r69318 | AD27: complete | AE27: TRUE | AF27: $9.99 | AG27: FALSE | AH27: 46242.565
A28: 942020 | B28: Grimm & Tonic: Aperitif | C28: 43861 | D28: 2020-01 | E28: 2020 | F28: 78.23 | G28: https://store.steampowered.com/app/942020/ | H28: https://vndb.org/v23383 | I28: 1170 | J28: FOUND | K28: 46 | L28: 28 | M28: 18 | N28: 0.60869565 | O28: Mixed | P28: FOUND | Q28: 低热度（≤198） | R28: 全年龄 | S28: TRUE | T28: FALSE | U28: VNDB minage=16; has_ero=false | V28: 16 | W28: FALSE | Y28: FALSE | Z28: ORIGINAL_INTERSECTION | AA28: TRUE | AB28: v23383 | AC28: r59581 | AD28: complete | AE28: TRUE | AF28: -75% | AG28: FALSE | AH28: 46242.565
A29: 1209330 | B29: Sakura Knight | C29: 43861 | D29: 2020-01 | E29: 2020 | F29: 78.23 | G29: https://store.steampowered.com/app/1209330/ | H29: https://vndb.org/v27835 | I29: 3973 | J29: FOUND | K29: 112 | L29: 92 | M29: 20 | N29: 0.82142857 | O29: Very Positive | P29: FOUND | Q29: 低热度（≤198） | R29: 全年龄 | S29: TRUE | T29: FALSE | U29: has_ero=false | W29: FALSE | Y29: FALSE | Z29: VNDB_ONLY_COMPLETE_INCREMENT | AA29: FALSE | AB29: v27835 | AC29: r69317 | AD29: complete | AE29: TRUE | AG29: FALSE | AH29: 46242.565
A30: 1139950 | B30: Two Weeks in Painland | C30: 43864 | D30: 2020-02 | E30: 2020 | F30: 78.13 | G30: https://store.steampowered.com/app/1139950/ | H30: https://vndb.org/v27946 | I30: 4690 | J30: FOUND | K30: 71 | L30: 61 | M30: 10 | N30: 0.85915493 | O30: Very Positive | P30: FOUND | Q30: 低热度（≤198） | R30: 全年龄 | S30: TRUE | T30: FALSE | U30: VNDB minage=16; has_ero=false | V30: 16 | W30: FALSE | Y30: FALSE | Z30: ORIGINAL_INTERSECTION | AA30: TRUE | AB30: v27946 | AC30: r69599 | AD30: complete | AE30: TRUE | AF30: Free | AG30: TRUE | AH30: 46242.565
A31: 1159660 | B31: Moe Era | C31: 43865 | D31: 2020-02 | E31: 2020 | F31: 78.09 | G31: https://store.steampowered.com/app/1159660/ | H31: https://vndb.org/v26814 | I31: 223698 | J31: FOUND | K31: 4818 | L31: 4215 | M31: 603 | N31: 0.87484433 | O31: Very Positive | P31: FOUND | Q31: 高热度（>198） | R31: 全年龄 | S31: TRUE | T31: FALSE | U31: has_ero=false | W31: FALSE | Y31: FALSE | Z31: ORIGINAL_INTERSECTION | AA31: TRUE | AB31: v26814 | AC31: r67090 | AD31: complete | AE31: TRUE | AF31: Free | AG31: TRUE | AH31: 46242.565
A32: 897220 | B32: Summer Pockets | C32: 43866 | D32: 2020-02 | E32: 2020 | F32: 78.06 | G32: https://store.steampowered.com/app/897220/ | H32: https://vndb.org/v20424 | I32: 99878 | J32: FOUND | K32: 4917 | L32: 4847 | M32: 70 | N32: 0.98576368 | O32: Overwhelmingly Positive | P32: FOUND | Q32: 高热度（>198） | R32: 全年龄 | S32: TRUE | T32: FALSE | U32: has_ero=false | W32: FALSE | Y32: FALSE | Z32: ORIGINAL_INTERSECTION | AA32: TRUE | AB32: v20424 | AC32: r71942 | AD32: complete | AE32: TRUE | AF32: $44.99 | AG32: FALSE | AH32: 46242.565
A33: 1207210 | B33: The foreigner | C33: 43866 | D33: 2020-02 | E33: 2020 | F33: 78.06 | G33: https://store.steampowered.com/app/1207210/ | H33: https://vndb.org/v27884 | I33: 1140 | J33: FOUND | K33: 32 | L33: 23 | M33: 9 | N33: 0.71875 | O33: Mostly Positive | P33: FOUND | Q33: 低热度（≤198） | R33: 全年龄 | S33: TRUE | T33: FALSE | U33: has_ero=false | W33: FALSE | Y33: FALSE | Z33: ORIGINAL_INTERSECTION | AA33: TRUE | AB33: v27884 | AC33: r87672 | AD33: complete | AE33: TRUE | AF33: $0.99 | AG33: FALSE | AH33: 46242.565
A34: 1174940 | B34: Kill or Love | C34: 43868 | D34: 2020-02 | E34: 2020 | F34: 78 | G34: https://store.steampowered.com/app/1174940/ | H34: https://vndb.org/v26356 | I34: 138834 | J34: FOUND | K34: 2183 | L34: 1946 | M34: 237 | N34: 0.89143381 | O34: Very Positive | P34: FOUND | Q34: 高热度（>198） | R34: 全年龄 | S34: TRUE | T34: FALSE | U34: VNDB minage=15; has_ero=false | V34: 15 | W34: FALSE | Y34: FALSE | Z34: ORIGINAL_INTERSECTION | AA34: TRUE | AB34: v26356 | AC34: r65534 | AD34: complete | AE34: TRUE | AF34: Free | AG34: TRUE | AH34: 46242.565
A35: 1224530 | B35: Naked News | C35: 43868 | D35: 2020-02 | E35: 2020 | F35: 78 | G35: https://store.steampowered.com/app/1224530/ | H35: https://vndb.org/v29089 | I35: 4879 | J35: FOUND | K35: 108 | L35: 70 | M35: 38 | N35: 0.64814815 | O35: Mixed | P35: FOUND | Q35: 低热度（≤198） | R35: 全年龄 | S35: TRUE | T35: FALSE | U35: has_ero=false | W35: FALSE | Y35: FALSE | Z35: ORIGINAL_INTERSECTION | AA35: TRUE | AB35: v29089 | AC35: r74121 | AD35: complete | AE35: TRUE | AF35: $0.99 | AG35: FALSE | AH35: 46242.565
A36: 1189440 | B36: VenusBlood FRONTIER International | C36: 43868 | D36: 2020-02 | E36: 2020 | F36: 78 | G36: https://store.steampowered.com/app/1189440/ | H36: https://vndb.org/v9409 | I36: 25607 | J36: FOUND | K36: 826 | L36: 774 | M36: 52 | N36: 0.937046 | O36: Very Positive | P36: FOUND | Q36: 高热度（>198） | R36: 全年龄 | S36: TRUE | T36: FALSE | U36: has_ero=false | W36: FALSE | Y36: FALSE | Z36: ORIGINAL_INTERSECTION | AA36: TRUE | AB36: v9409 | AC36: r84869 | AD36: complete | AE36: TRUE | AF36: $39.99 | AG36: FALSE | AH36: 46242.565
A37: 1209610 | B37: Virtually Real Life | C37: 43868 | D37: 2020-02 | E37: 2020 | F37: 78 | G37: https://store.steampowered.com/app/1209610/ | H37: https://vndb.org/v27979 | I37: 40 | J37: FOUND | K37: 3 | L37: 2 | M37: 1 | N37: 0.66666667 | O37: 3 user reviews | P37: FOUND | Q37: 低热度（≤198） | R37: 全年龄 | S37: TRUE | T37: FALSE | U37: VNDB minage=12; has_ero=false | V37: 12 | W37: FALSE | Y37: FALSE | Z37: ORIGINAL_INTERSECTION | AA37: TRUE | AB37: v27979 | AC37: r69684 | AD37: complete | AE37: TRUE | AF37: $3.99 | AG37: FALSE | AH37: 46242.565
A38: 1211650 | B38: Cirno's Perfect Summer Vacation | C38: 43871 | D38: 2020-02 | E38: 2020 | F38: 77.9 | G38: https://store.steampowered.com/app/1211650/ | H38: https://vndb.org/v26730 | I38: 8550 | J38: FOUND | K38: 95 | L38: 82 | M38: 13 | N38: 0.86315789 | O38: Very Positive | P38: FOUND | Q38: 低热度（≤198） | R38: 全年龄 | S38: TRUE | T38: FALSE | U38: VNDB minage=13; has_ero=false | V38: 13 | W38: FALSE | Y38: FALSE | Z38: ORIGINAL_INTERSECTION | AA38: TRUE | AB38: v26730 | AC38: r66855 | AD38: complete | AE38: TRUE | AF38: Free | AG38: TRUE | AH38: 46242.565
A39: 1232180 | B39: Sakuya Izayoi Gives You Advice And Dabs | C39: 43871 | D39: 2020-02 | E39: 2020 | F39: 77.9 | G39: https://store.steampowered.com/app/1232180/ | H39: https://vndb.org/v27913 | I39: 77050 | J39: FOUND | K39: 2412 | L39: 2351 | M39: 61 | N39: 0.97470978 | O39: Overwhelmingly Positive | P39: FOUND | Q39: 高热度（>198） | R39: 全年龄 | S39: TRUE | T39: FALSE | U39: has_ero=false | W39: FALSE | Y39: FALSE | Z39: ORIGINAL_INTERSECTION | AA39: TRUE | AB39: v27913 | AC39: r123940 | AD39: complete | AE39: TRUE | AF39: $0.99 | AG39: FALSE | AH39: 46242.565
A40: 812590 | B40: Awakening of Celestial | C40: 43873 | D40: 2020-02 | E40: 2020 | F40: 77.83 | G40: https://store.steampowered.com/app/812590/ | H40: https://vndb.org/v27929 | I40: 33 | J40: FOUND | K40: 5 | L40: 5 | M40: 0 | N40: 1 | O40: 5 user reviews | P40: FOUND | Q40: 低热度（≤198） | R40: 全年龄 | S40: TRUE | T40: FALSE | U40: has_ero=false | W40: FALSE | Y40: FALSE | Z40: ORIGINAL_INTERSECTION | AA40: TRUE | AB40: v27929 | AC40: r69544 | AD40: complete | AE40: TRUE | AF40: $9.99 | AG40: FALSE | AH40: 46242.565
...

Sheet 月度统计
A1: release_month | B1: game_count | C1: high_heat_count | D1: low_heat_count | E1: unknown_review_count | F1: all_ages_count | G1: not_all_ages_count | H1: unknown_age_count | I1: copies_sold_sum | J1: copies_sold_known
A2: 2020-01 | B2: 28 | C2: 8 | D2: 20 | E2: 0 | F2: 23 | G2: 5 | H2: 0 | I2: 835261 | J2: 26
A3: 2020-02 | B3: 46 | C3: 15 | D3: 31 | E3: 0 | F3: 36 | G3: 10 | H3: 0 | I3: 2135287 | J3: 44
A4: 2020-03 | B4: 31 | C4: 9 | D4: 22 | E4: 0 | F4: 24 | G4: 7 | H4: 0 | I4: 441906 | J4: 30
A5: 2020-04 | B5: 46 | C5: 14 | D5: 32 | E5: 0 | F5: 37 | G5: 9 | H5: 0 | I5: 379809 | J5: 39
A6: 2020-05 | B6: 37 | C6: 11 | D6: 26 | E6: 0 | F6: 29 | G6: 8 | H6: 0 | I6: 1349408 | J6: 30
A7: 2020-06 | B7: 44 | C7: 9 | D7: 35 | E7: 0 | F7: 40 | G7: 4 | H7: 0 | I7: 3513450 | J7: 42
A8: 2020-07 | B8: 50 | C8: 16 | D8: 34 | E8: 0 | F8: 41 | G8: 9 | H8: 0 | I8: 405896 | J8: 42
A9: 2020-08 | B9: 40 | C9: 12 | D9: 28 | E9: 0 | F9: 31 | G9: 9 | H9: 0 | I9: 1045748 | J9: 35
A10: 2020-09 | B10: 34 | C10: 8 | D10: 26 | E10: 0 | F10: 28 | G10: 6 | H10: 0 | I10: 302224 | J10: 32
A11: 2020-10 | B11: 53 | C11: 17 | D11: 36 | E11: 0 | F11: 44 | G11: 9 | H11: 0 | I11: 1005416 | J11: 46
A12: 2020-11 | B12: 44 | C12: 10 | D12: 34 | E12: 0 | F12: 39 | G12: 5 | H12: 0 | I12: 1462383 | J12: 36
A13: 2020-12 | B13: 45 | C13: 13 | D13: 32 | E13: 0 | F13: 33 | G13: 12 | H13: 0 | I13: 1132433 | J13: 41
... A73: 2025-12 | B73: 94 | C73: 9 | D73: 85 | E73: 0 | F73: 71 | G73: 23 | H73: 0 | I73: 789036 | J73: 83

Sheet 年度统计
A1: release_year | B1: game_count | C1: high_heat_count | D1: low_heat_count | E1: unknown_review_count | F1: all_ages_count | G1: not_all_ages_count | H1: unknown_age_count | I1: copies_sold_sum | J1: copies_sold_known
A2: 2020 | B2: 498 | C2: 142 | D2: 356 | E2: 0 | F2: 405 | G2: 93 | H2: 0 | I2: 14009221 | J2: 443
A3: 2021 | B3: 590 | C3: 152 | D3: 438 | E3: 0 | F3: 432 | G3: 158 | H3: 0 | I3: 14631664 | J3: 530
A4: 2022 | B4: 758 | C4: 143 | D4: 615 | E4: 0 | F4: 495 | G4: 263 | H4: 0 | I4: 11267193 | J4: 697
A5: 2023 | B5: 814 | C5: 143 | D5: 671 | E5: 0 | F5: 559 | G5: 255 | H5: 0 | I5: 12408258 | J5: 742
A6: 2024 | B6: 992 | C6: 192 | D6: 800 | E6: 0 | F6: 705 | G6: 287 | H6: 0 | I6: 10412483 | J6: 911
A7: 2025 | B7: 1008 | C7: 162 | D7: 846 | E7: 0 | F7: 740 | G7: 268 | H7: 0 | I7: 11701567 | J7: 936

Sheet 图表数据
A1: 月份 | B1: 全部游戏 | D1: 年份 | E1: 全部游戏 | G1: 月份 | H1: 高热度（>198） | I1: 低热度（≤198） | K1: 年份 | L1: 高热度（>198） | M1: 低热度（≤198） | O1: 月份 | P1: 全年龄 | Q1: 非全年龄 | R1: 未知 | T1: 年份 | U1: 全年龄 | V1: 非全年龄 | W1: 未知 | Y1: 上市月数 | Z1: 全部 log10销量 | AA1: 高热度（>198） log10销量 | AB1: 低热度（≤198） log10销量 | AC1: 全年龄 log10销量 | AD1: 非全年龄 log10销量 | AF1: 分类 | AG1: 游戏数
A2: =月度统计!A2 -> 2020-01 | B2: =月度统计!B2 -> 28 | D2: =年度统计!A2 -> 2020 | E2: =年度统计!B2 -> 498 | G2: =月度统计!A2 -> 2020-01 | H2: =月度统计!C2 -> 8 | I2: =月度统计!D2 -> 20 | K2: =年度统计!A2 -> 2020 | L2: =年度统计!C2 -> 142 | M2: =年度统计!D2 -> 356 | O2: =月度统计!A2 -> 2020-01 | P2: =月度统计!F2 -> 23 | Q2: =月度统计!G2 -> 5 | R2: =月度统计!H2 -> 0 | T2: =年度统计!A2 -> 2020 | U2: =年度统计!F2 -> 405 | V2: =年度统计!G2 -> 93 | W2: =年度统计!H2 -> 0 | Y2: =游戏总表!F2 -> 79.21 | Z2: =IF(游戏总表!I2>0,LOG(游戏总表!I2,10),"") -> 2.4424798 | AA2: =IF(AND(游戏总表!I2>0,游戏总表!Q2="高热度（>198）"),LOG(游戏总表!I2,10),"") | AB2: =IF(AND(游戏总表!I2>0,游戏总表!Q2="低热度（≤198）"),LOG(游戏总表!I2,10),"") -> 2.4424798 | AC2: =IF(AND(游戏总表!I2>0,游戏总表!R2="全年龄"),LOG(游戏总表!I2,10),"") -> 2.4424798 | AD2: =IF(AND(游戏总表!I2>0,游戏总表!R2="非全年龄"),LOG(游戏总表!I2,10),"") | AF2: 全年龄 | AG2: =COUNTIF(游戏总表!$R$2:$R$4661,AF2) -> 3336
A3: =月度统计!A3 -> 2020-02 | B3: =月度统计!B3 -> 46 | D3: =年度统计!A3 -> 2021 | E3: =年度统计!B3 -> 590 | G3: =月度统计!A3 -> 2020-02 | H3: =月度统计!C3 -> 15 | I3: =月度统计!D3 -> 31 | K3: =年度统计!A3 -> 2021 | L3: =年度统计!C3 -> 152 | M3: =年度统计!D3 -> 438 | O3: =月度统计!A3 -> 2020-02 | P3: =月度统计!F3 -> 36 | Q3: =月度统计!G3 -> 10 | R3: =月度统计!H3 -> 0 | T3: =年度统计!A3 -> 2021 | U3: =年度统计!F3 -> 432 | V3: =年度统计!G3 -> 158 | W3: =年度统计!H3 -> 0 | Y3: =游戏总表!F3 -> 79.18 | Z3: =IF(游戏总表!I3>0,LOG(游戏总表!I3,10),"") -> 4.4243752 | AA3: =IF(AND(游戏总表!I3>0,游戏总表!Q3="高热度（>198）"),LOG(游戏总表!I3,10),"") -> 4.4243752 | AB3: =IF(AND(游戏总表!I3>0,游戏总表!Q3="低热度（≤198）"),LOG(游戏总表!I3,10),"") | AC3: =IF(AND(游戏总表!I3>0,游戏总表!R3="全年龄"),LOG(游戏总表!I3,10),"") -> 4.4243752 | AD3: =IF(AND(游戏总表!I3>0,游戏总表!R3="非全年龄"),LOG(游戏总表!I3,10),"") | AF3: 非全年龄 | AG3: =COUNTIF(游戏总表!$R$2:$R$4661,AF3) -> 1324
A4: =月度统计!A4 -> 2020-03 | B4: =月度统计!B4 -> 31 | D4: =年度统计!A4 -> 2022 | E4: =年度统计!B4 -> 758 | G4: =月度统计!A4 -> 2020-03 | H4: =月度统计!C4 -> 9 | I4: =月度统计!D4 -> 22 | K4: =年度统计!A4 -> 2022 | L4: =年度统计!C4 -> 143 | M4: =年度统计!D4 -> 615 | O4: =月度统计!A4 -> 2020-03 | P4: =月度统计!F4 -> 24 | Q4: =月度统计!G4 -> 7 | R4: =月度统计!H4 -> 0 | T4: =年度统计!A4 -> 2022 | U4: =年度统计!F4 -> 495 | V4: =年度统计!G4 -> 263 | W4: =年度统计!H4 -> 0 | Y4: =游戏总表!F4 -> 79.18 | Z4: =IF(游戏总表!I4>0,LOG(游戏总表!I4,10),"") -> 4.9551969 | AA4: =IF(AND(游戏总表!I4>0,游戏总表!Q4="高热度（>198）"),LOG(游戏总表!I4,10),"") -> 4.9551969 | AB4: =IF(AND(游戏总表!I4>0,游戏总表!Q4="低热度（≤198）"),LOG(游戏总表!I4,10),"") | AC4: =IF(AND(游戏总表!I4>0,游戏总表!R4="全年龄"),LOG(游戏总表!I4,10),"") -> 4.9551969 | AD4: =IF(AND(游戏总表!I4>0,游戏总表!R4="非全年龄"),LOG(游戏总表!I4,10),"") | AF4: 未知 | AG4: =COUNTIF(游戏总表!$R$2:$R$4661,AF4) -> 0
A5: =月度统计!A5 -> 2020-04 | B5: =月度统计!B5 -> 46 | D5: =年度统计!A5 -> 2023 | E5: =年度统计!B5 -> 814 | G5: =月度统计!A5 -> 2020-04 | H5: =月度统计!C5 -> 14 | I5: =月度统计!D5 -> 32 | K5: =年度统计!A5 -> 2023 | L5: =年度统计!C5 -> 143 | M5: =年度统计!D5 -> 671 | O5: =月度统计!A5 -> 2020-04 | P5: =月度统计!F5 -> 37 | Q5: =月度统计!G5 -> 9 | R5: =月度统计!H5 -> 0 | T5: =年度统计!A5 -> 2023 | U5: =年度统计!F5 -> 559 | V5: =年度统计!G5 -> 255 | W5: =年度统计!H5 -> 0 | Y5: =游戏总表!F5 -> 79.15 | Z5: =IF(游戏总表!I5>0,LOG(游戏总表!I5,10),"") -> 2.071882 | AA5: =IF(AND(游戏总表!I5>0,游戏总表!Q5="高热度（>198）"),LOG(游戏总表!I5,10),"") | AB5: =IF(AND(游戏总表!I5>0,游戏总表!Q5="低热度（≤198）"),LOG(游戏总表!I5,10),"") -> 2.071882 | AC5: =IF(AND(游戏总表!I5>0,游戏总表!R5="全年龄"),LOG(游戏总表!I5,10),"") -> 2.071882 | AD5: =IF(AND(游戏总表!I5>0,游戏总表!R5="非全年龄"),LOG(游戏总表!I5,10),"")
A6: =月度统计!A6 -> 2020-05 | B6: =月度统计!B6 -> 37 | D6: =年度统计!A6 -> 2024 | E6: =年度统计!B6 -> 992 | G6: =月度统计!A6 -> 2020-05 | H6: =月度统计!C6 -> 11 | I6: =月度统计!D6 -> 26 | K6: =年度统计!A6 -> 2024 | L6: =年度统计!C6 -> 192 | M6: =年度统计!D6 -> 800 | O6: =月度统计!A6 -> 2020-05 | P6: =月度统计!F6 -> 29 | Q6: =月度统计!G6 -> 8 | R6: =月度统计!H6 -> 0 | T6: =年度统计!A6 -> 2024 | U6: =年度统计!F6 -> 705 | V6: =年度统计!G6 -> 287 | W6: =年度统计!H6 -> 0 | Y6: =游戏总表!F6 -> 78.92 | Z6: =IF(游戏总表!I6>0,LOG(游戏总表!I6,10),"") -> 2.146128 | AA6: =IF(AND(游戏总表!I6>0,游戏总表!Q6="高热度（>198）"),LOG(游戏总表!I6,10),"") | AB6: =IF(AND(游戏总表!I6>0,游戏总表!Q6="低热度（≤198）"),LOG(游戏总表!I6,10),"") -> 2.146128 | AC6: =IF(AND(游戏总表!I6>0,游戏总表!R6="全年龄"),LOG(游戏总表!I6,10),"") -> 2.146128 | AD6: =IF(AND(游戏总表!I6>0,游戏总表!R6="非全年龄"),LOG(游戏总表!I6,10),"")
A7: =月度统计!A7 -> 2020-06 | B7: =月度统计!B7 -> 44 | D7: =年度统计!A7 -> 2025 | E7: =年度统计!B7 -> 1008 | G7: =月度统计!A7 -> 2020-06 | H7: =月度统计!C7 -> 9 | I7: =月度统计!D7 -> 35 | K7: =年度统计!A7 -> 2025 | L7: =年度统计!C7 -> 162 | M7: =年度统计!D7 -> 846 | O7: =月度统计!A7 -> 2020-06 | P7: =月度统计!F7 -> 40 | Q7: =月度统计!G7 -> 4 | R7: =月度统计!H7 -> 0 | T7: =年度统计!A7 -> 2025 | U7: =年度统计!F7 -> 740 | V7: =年度统计!G7 -> 268 | W7: =年度统计!H7 -> 0 | Y7: =游戏总表!F7 -> 78.82 | Z7: =IF(游戏总表!I7>0,LOG(游戏总表!I7,10),"") -> 4.8835365 | AA7: =IF(AND(游戏总表!I7>0,游戏总表!Q7="高热度（>198）"),LOG(游戏总表!I7,10),"") -> 4.8835365 | AB7: =IF(AND(游戏总表!I7>0,游戏总表!Q7="低热度（≤198）"),LOG(游戏总表!I7,10),"") | AC7: =IF(AND(游戏总表!I7>0,游戏总表!R7="全年龄"),LOG(游戏总表!I7,10),"") -> 4.8835365 | AD7: =IF(AND(游戏总表!I7>0,游戏总表!R7="非全年龄"),LOG(游戏总表!I7,10),"")
A8: =月度统计!A8 -> 2020-07 | B8: =月度统计!B8 -> 50 | G8: =月度统计!A8 -> 2020-07 | H8: =月度统计!C8 -> 16 | I8: =月度统计!D8 -> 34 | O8: =月度统计!A8 -> 2020-07 | P8: =月度统计!F8 -> 41 | Q8: =月度统计!G8 -> 9 | R8: =月度统计!H8 -> 0 | Y8: =游戏总表!F8 -> 78.78 | Z8: =IF(游戏总表!I8>0,LOG(游戏总表!I8,10),"") -> 2.9786369 | AA8: =IF(AND(游戏总表!I8>0,游戏总表!Q8="高热度（>198）"),LOG(游戏总表!I8,10),"") | AB8: =IF(AND(游戏总表!I8>0,游戏总表!Q8="低热度（≤198）"),LOG(游戏总表!I8,10),"") -> 2.9786369 | AC8: =IF(AND(游戏总表!I8>0,游戏总表!R8="全年龄"),LOG(游戏总表!I8,10),"") -> 2.9786369 | AD8: =IF(AND(游戏总表!I8>0,游戏总表!R8="非全年龄"),LOG(游戏总表!I8,10),"")
A9: =月度统计!A9 -> 2020-08 | B9: =月度统计!B9 -> 40 | G9: =月度统计!A9 -> 2020-08 | H9: =月度统计!C9 -> 12 | I9: =月度统计!D9 -> 28 | O9: =月度统计!A9 -> 2020-08 | P9: =月度统计!F9 -> 31 | Q9: =月度统计!G9 -> 9 | R9: =月度统计!H9 -> 0 | Y9: =游戏总表!F9 -> 78.78 | Z9: =IF(游戏总表!I9>0,LOG(游戏总表!I9,10),"") -> 4.85083 | AA9: =IF(AND(游戏总表!I9>0,游戏总表!Q9="高热度（>198）"),LOG(游戏总表!I9,10),"") -> 4.85083 | AB9: =IF(AND(游戏总表!I9>0,游戏总表!Q9="低热度（≤198）"),LOG(游戏总表!I9,10),"") | AC9: =IF(AND(游戏总表!I9>0,游戏总表!R9="全年龄"),LOG(游戏总表!I9,10),"") -> 4.85083 | AD9: =IF(AND(游戏总表!I9>0,游戏总表!R9="非全年龄"),LOG(游戏总表!I9,10),"")
A10: =月度统计!A10 -> 2020-09 | B10: =月度统计!B10 -> 34 | G10: =月度统计!A10 -> 2020-09 | H10: =月度统计!C10 -> 8 | I10: =月度统计!D10 -> 26 | O10: =月度统计!A10 -> 2020-09 | P10: =月度统计!F10 -> 28 | Q10: =月度统计!G10 -> 6 | R10: =月度统计!H10 -> 0 | Y10: =游戏总表!F10 -> 78.72 | Z10: =IF(游戏总表!I10>0,LOG(游戏总表!I10,10),"") -> 4.0480143 | AA10: =IF(AND(游戏总表!I10>0,游戏总表!Q10="高热度（>198）"),LOG(游戏总表!I10,10),"") | AB10: =IF(AND(游戏总表!I10>0,游戏总表!Q10="低热度（≤198）"),LOG(游戏总表!I10,10),"") -> 4.0480143 | AC10: =IF(AND(游戏总表!I10>0,游戏总表!R10="全年龄"),LOG(游戏总表!I10,10),"") -> 4.0480143 | AD10: =IF(AND(游戏总表!I10>0,游戏总表!R10="非全年龄"),LOG(游戏总表!I10,10),"")
A11: =月度统计!A11 -> 2020-10 | B11: =月度统计!B11 -> 53 | G11: =月度统计!A11 -> 2020-10 | H11: =月度统计!C11 -> 17 | I11: =月度统计!D11 -> 36 | O11: =月度统计!A11 -> 2020-10 | P11: =月度统计!F11 -> 44 | Q11: =月度统计!G11 -> 9 | R11: =月度统计!H11 -> 0 | Y11: =游戏总表!F11 -> 78.69 | Z11: =IF(游戏总表!I11>0,LOG(游戏总表!I11,10),"") -> 2.5658478 | AA11: =IF(AND(游戏总表!I11>0,游戏总表!Q11="高热度（>198）"),LOG(游戏总表!I11,10),"") | AB11: =IF(AND(游戏总表!I11>0,游戏总表!Q11="低热度（≤198）"),LOG(游戏总表!I11,10),"") -> 2.5658478 | AC11: =IF(AND(游戏总表!I11>0,游戏总表!R11="全年龄"),LOG(游戏总表!I11,10),"") -> 2.5658478 | AD11: =IF(AND(游戏总表!I11>0,游戏总表!R11="非全年龄"),LOG(游戏总表!I11,10),"")
A12: =月度统计!A12 -> 2020-11 | B12: =月度统计!B12 -> 44 | G12: =月度统计!A12 -> 2020-11 | H12: =月度统计!C12 -> 10 | I12: =月度统计!D12 -> 34 | O12: =月度统计!A12 -> 2020-11 | P12: =月度统计!F12 -> 39 | Q12: =月度统计!G12 -> 5 | R12: =月度统计!H12 -> 0 | Y12: =游戏总表!F12 -> 78.69 | Z12: =IF(游戏总表!I12>0,LOG(游戏总表!I12,10),"") -> 3.1271048 | AA12: =IF(AND(游戏总表!I12>0,游戏总表!Q12="高热度（>198）"),LOG(游戏总表!I12,10),"") | AB12: =IF(AND(游戏总表!I12>0,游戏总表!Q12="低热度（≤198）"),LOG(游戏总表!I12,10),"") -> 3.1271048 | AC12: =IF(AND(游戏总表!I12>0,游戏总表!R12="全年龄"),LOG(游戏总表!I12,10),"") | AD12: =IF(AND(游戏总表!I12>0,游戏总表!R12="非全年龄"),LOG(游戏总表!I12,10),"") -> 3.1271048
A13: =月度统计!A13 -> 2020-12 | B13: =月度统计!B13 -> 45 | G13: =月度统计!A13 -> 2020-12 | H13: =月度统计!C13 -> 13 | I13: =月度统计!D13 -> 32 | O13: =月度统计!A13 -> 2020-12 | P13: =月度统计!F13 -> 33 | Q13: =月度统计!G13 -> 12 | R13: =月度统计!H13 -> 0 | Y13: =游戏总表!F13 -> 78.69 | Z13: =IF(游戏总表!I13>0,LOG(游戏总表!I13,10),"") -> 2.146128 | AA13: =IF(AND(游戏总表!I13>0,游戏总表!Q13="高热度（>198）"),LOG(游戏总表!I13,10),"") | AB13: =IF(AND(游戏总表!I13>0,游戏总表!Q13="低热度（≤198）"),LOG(游戏总表!I13,10),"") -> 2.146128 | AC13: =IF(AND(游戏总表!I13>0,游戏总表!R13="全年龄"),LOG(游戏总表!I13,10),"") -> 2.146128 | AD13: =IF(AND(游戏总表!I13>0,游戏总表!R13="非全年龄"),LOG(游戏总表!I13,10),"")
A14: =月度统计!A14 -> 2021-01 | B14: =月度统计!B14 -> 44 | G14: =月度统计!A14 -> 2021-01 | H14: =月度统计!C14 -> 13 | I14: =月度统计!D14 -> 31 | O14: =月度统计!A14 -> 2021-01 | P14: =月度统计!F14 -> 37 | Q14: =月度统计!G14 -> 7 | R14: =月度统计!H14 -> 0 | Y14: =游戏总表!F14 -> 78.69 | Z14: =IF(游戏总表!I14>0,LOG(游戏总表!I14,10),"") | AA14: =IF(AND(游戏总表!I14>0,游戏总表!Q14="高热度（>198）"),LOG(游戏总表!I14,10),"") | AB14: =IF(AND(游戏总表!I14>0,游戏总表!Q14="低热度（≤198）"),LOG(游戏总表!I14,10),"") | AC14: =IF(AND(游戏总表!I14>0,游戏总表!R14="全年龄"),LOG(游戏总表!I14,10),"") | AD14: =IF(AND(游戏总表!I14>0,游戏总表!R14="非全年龄"),LOG(游戏总表!I14,10),"")
A15: =月度统计!A15 -> 2021-02 | B15: =月度统计!B15 -> 42 | G15: =月度统计!A15 -> 2021-02 | H15: =月度统计!C15 -> 14 | I15: =月度统计!D15 -> 28 | O15: =月度统计!A15 -> 2021-02 | P15: =月度统计!F15 -> 31 | Q15: =月度统计!G15 -> 11 | R15: =月度统计!H15 -> 0 | Y15: =游戏总表!F15 -> 78.69 | Z15: =IF(游戏总表!I15>0,LOG(游戏总表!I15,10),"") -> 2.7143298 | AA15: =IF(AND(游戏总表!I15>0,游戏总表!Q15="高热度（>198）"),LOG(游戏总表!I15,10),"") | AB15: =IF(AND(游戏总表!I15>0,游戏总表!Q15="低热度（≤198）"),LOG(游戏总表!I15,10),"") -> 2.7143298 | AC15: =IF(AND(游戏总表!I15>0,游戏总表!R15="全年龄"),LOG(游戏总表!I15,10),"") -> 2.7143298 | AD15: =IF(AND(游戏总表!I15>0,游戏总表!R15="非全年龄"),LOG(游戏总表!I15,10),"")
A16: =月度统计!A16 -> 2021-03 | B16: =月度统计!B16 -> 39 | G16: =月度统计!A16 -> 2021-03 | H16: =月度统计!C16 -> 5 | I16: =月度统计!D16 -> 34 | O16: =月度统计!A16 -> 2021-03 | P16: =月度统计!F16 -> 26 | Q16: =月度统计!G16 -> 13 | R16: =月度统计!H16 -> 0 | Y16: =游戏总表!F16 -> 78.59 | Z16: =IF(游戏总表!I16>0,LOG(游戏总表!I16,10),"") -> 2.456366 | AA16: =IF(AND(游戏总表!I16>0,游戏总表!Q16="高热度（>198）"),LOG(游戏总表!I16,10),"") | AB16: =IF(AND(游戏总表!I16>0,游戏总表!Q16="低热度（≤198）"),LOG(游戏总表!I16,10),"") -> 2.456366 | AC16: =IF(AND(游戏总表!I16>0,游戏总表!R16="全年龄"),LOG(游戏总表!I16,10),"") -> 2.456366 | AD16: =IF(AND(游戏总表!I16>0,游戏总表!R16="非全年龄"),LOG(游戏总表!I16,10),"")
A17: =月度统计!A17 -> 2021-04 | B17: =月度统计!B17 -> 45 | G17: =月度统计!A17 -> 2021-04 | H17: =月度统计!C17 -> 14 | I17: =月度统计!D17 -> 31 | O17: =月度统计!A17 -> 2021-04 | P17: =月度统计!F17 -> 34 | Q17: =月度统计!G17 -> 11 | R17: =月度统计!H17 -> 0 | Y17: =游戏总表!F17 -> 78.59 | Z17: =IF(游戏总表!I17>0,LOG(游戏总表!I17,10),"") -> 2.2174839 | AA17: =IF(AND(游戏总表!I17>0,游戏总表!Q17="高热度（>198）"),LOG(游戏总表!I17,10),"") | AB17: =IF(AND(游戏总表!I17>0,游戏总表!Q17="低热度（≤198）"),LOG(游戏总表!I17,10),"") -> 2.2174839 | AC17: =IF(AND(游戏总表!I17>0,游戏总表!R17="全年龄"),LOG(游戏总表!I17,10),"") -> 2.2174839 | AD17: =IF(AND(游戏总表!I17>0,游戏总表!R17="非全年龄"),LOG(游戏总表!I17,10),"")
A18: =月度统计!A18 -> 2021-05 | B18: =月度统计!B18 -> 43 | G18: =月度统计!A18 -> 2021-05 | H18: =月度统计!C18 -> 12 | I18: =月度统计!D18 -> 31 | O18: =月度统计!A18 -> 2021-05 | P18: =月度统计!F18 -> 32 | Q18: =月度统计!G18 -> 11 | R18: =月度统计!H18 -> 0 | Y18: =游戏总表!F18 -> 78.49 | Z18: =IF(游戏总表!I18>0,LOG(游戏总表!I18,10),"") -> 4.7184934 | AA18: =IF(AND(游戏总表!I18>0,游戏总表!Q18="高热度（>198）"),LOG(游戏总表!I18,10),"") -> 4.7184934 | AB18: =IF(AND(游戏总表!I18>0,游戏总表!Q18="低热度（≤198）"),LOG(游戏总表!I18,10),"") | AC18: =IF(AND(游戏总表!I18>0,游戏总表!R18="全年龄"),LOG(游戏总表!I18,10),"") -> 4.7184934 | AD18: =IF(AND(游戏总表!I18>0,游戏总表!R18="非全年龄"),LOG(游戏总表!I18,10),"")
A19: =月度统计!A19 -> 2021-06 | B19: =月度统计!B19 -> 45 | G19: =月度统计!A19 -> 2021-06 | H19: =月度统计!C19 -> 13 | I19: =月度统计!D19 -> 32 | O19: =月度统计!A19 -> 2021-06 | P19: =月度统计!F19 -> 36 | Q19: =月度统计!G19 -> 9 | R19: =月度统计!H19 -> 0 | Y19: =游戏总表!F19 -> 78.49 | Z19: =IF(游戏总表!I19>0,LOG(游戏总表!I19,10),"") -> 4.5528142 | AA19: =IF(AND(游戏总表!I19>0,游戏总表!Q19="高热度（>198）"),LOG(游戏总表!I19,10),"") -> 4.5528142 | AB19: =IF(AND(游戏总表!I19>0,游戏总表!Q19="低热度（≤198）"),LOG(游戏总表!I19,10),"") | AC19: =IF(AND(游戏总表!I19>0,游戏总表!R19="全年龄"),LOG(游戏总表!I19,10),"") -> 4.5528142 | AD19: =IF(AND(游戏总表!I19>0,游戏总表!R19="非全年龄"),LOG(游戏总表!I19,10),"")
... A73: =月度统计!A73 -> 2025-12 | B73: =月度统计!B73 -> 94 | G73: =月度统计!A73 -> 2025-12 | H73: =月度统计!C73 -> 9 | I73: =月度统计!D73 -> 85 | O73: =月度统计!A73 -> 2025-12 | P73: =月度统计!F73 -> 71 | Q73: =月度统计!G73 -> 23 | R73: =月度统计!H73 -> 0 | Y73: =游戏总表!F73 -> 77.31 | Z73: =IF(游戏总表!I73>0,LOG(游戏总表!I73,10),"") -> 5.2262312 | AA73: =IF(AND(游戏总表!I73>0,游戏总表!Q73="高热度（>198）"),LOG(游戏总表!I73,10),"") -> 5.2262312 | AB73: =IF(AND(游戏总表!I73>0,游戏总表!Q73="低热度（≤198）"),LOG(游戏总表!I73,10),"") | AC73: =IF(AND(游戏总表!I73>0,游戏总表!R73="全年龄"),LOG(游戏总表!I73,10),"") -> 5.2262312 | AD73: =IF(AND(游戏总表!I73>0,游戏总表!R73="非全年龄"),LOG(游戏总表!I73,10),"")
Y74: =游戏总表!F74 -> 77.31 | Z74: =IF(游戏总表!I74>0,LOG(游戏总表!I74,10),"") -> 2.5899496 | AA74: =IF(AND(游戏总表!I74>0,游戏总表!Q74="高热度（>198）"),LOG(游戏总表!I74,10),"") | AB74: =IF(AND(游戏总表!I74>0,游戏总表!Q74="低热度（≤198）"),LOG(游戏总表!I74,10),"") -> 2.5899496 | AC74: =IF(AND(游戏总表!I74>0,游戏总表!R74="全年龄"),LOG(游戏总表!I74,10),"") -> 2.5899496 | AD74: =IF(AND(游戏总表!I74>0,游戏总表!R74="非全年龄"),LOG(游戏总表!I74,10),"")
Y75: =游戏总表!F75 -> 77.27 | Z75: =IF(游戏总表!I75>0,LOG(游戏总表!I75,10),"") -> 2.4265113 | AA75: =IF(AND(游戏总表!I75>0,游戏总表!Q75="高热度（>198）"),LOG(游戏总表!I75,10),"") | AB75: =IF(AND(游戏总表!I75>0,游戏总表!Q75="低热度（≤198）"),LOG(游戏总表!I75,10),"") -> 2.4265113 | AC75: =IF(AND(游戏总表!I75>0,游戏总表!R75="全年龄"),LOG(游戏总表!I75,10),"") -> 2.4265113 | AD75: =IF(AND(游戏总表!I75>0,游戏总表!R75="非全年龄"),LOG(游戏总表!I75,10),"")
Y76: =游戏总表!F76 -> 77.21 | Z76: =IF(游戏总表!I76>0,LOG(游戏总表!I76,10),"") -> 2.6434527 | AA76: =IF(AND(游戏总表!I76>0,游戏总表!Q76="高热度（>198）"),LOG(游戏总表!I76,10),"") | AB76: =IF(AND(游戏总表!I76>0,游戏总表!Q76="低热度（≤198）"),LOG(游戏总表!I76,10),"") -> 2.6434527 | AC76: =IF(AND(游戏总表!I76>0,游戏总表!R76="全年龄"),LOG(游戏总表!I76,10),"") | AD76: =IF(AND(游戏总表!I76>0,游戏总表!R76="非全年龄"),LOG(游戏总表!I76,10),"") -> 2.6434527
Y77: =游戏总表!F77 -> 77.21 | Z77: =IF(游戏总表!I77>0,LOG(游戏总表!I77,10),"") -> 5.1513085 | AA77: =IF(AND(游戏总表!I77>0,游戏总表!Q77="高热度（>198）"),LOG(游戏总表!I77,10),"") -> 5.1513085 | AB77: =IF(AND(游戏总表!I77>0,游戏总表!Q77="低热度（≤198）"),LOG(游戏总表!I77,10),"") | AC77: =IF(AND(游戏总表!I77>0,游戏总表!R77="全年龄"),LOG(游戏总表!I77,10),"") -> 5.1513085 | AD77: =IF(AND(游戏总表!I77>0,游戏总表!R77="非全年龄"),LOG(游戏总表!I77,10),"")
Y78: =游戏总表!F78 -> 77.17 | Z78: =IF(游戏总表!I78>0,LOG(游戏总表!I78,10),"") -> 1.4771213 | AA78: =IF(AND(游戏总表!I78>0,游戏总表!Q78="高热度（>198）"),LOG(游戏总表!I78,10),"") | AB78: =IF(AND(游戏总表!I78>0,游戏总表!Q78="低热度（≤198）"),LOG(游戏总表!I78,10),"") -> 1.4771213 | AC78: =IF(AND(游戏总表!I78>0,游戏总表!R78="全年龄"),LOG(游戏总表!I78,10),"") -> 1.4771213 | AD78: =IF(AND(游戏总表!I78>0,游戏总表!R78="非全年龄"),LOG(游戏总表!I78,10),"")
Y79: =游戏总表!F79 -> 77.17 | Z79: =IF(游戏总表!I79>0,LOG(游戏总表!I79,10),"") -> 2.5263393 | AA79: =IF(AND(游戏总表!I79>0,游戏总表!Q79="高热度（>198）"),LOG(游戏总表!I79,10),"") | AB79: =IF(AND(游戏总表!I79>0,游戏总表!Q79="低热度（≤198）"),LOG(游戏总表!I79,10),"") -> 2.5263393 | AC79: =IF(AND(游戏总表!I79>0,游戏总表!R79="全年龄"),LOG(游戏总表!I79,10),"") -> 2.5263393 | AD79: =IF(AND(游戏总表!I79>0,游戏总表!R79="非全年龄"),LOG(游戏总表!I79,10),"")
Y80: =游戏总表!F80 -> 77.11 | Z80: =IF(游戏总表!I80>0,LOG(游戏总表!I80,10),"") -> 3.7218106 | AA80: =IF(AND(游戏总表!I80>0,游戏总表!Q80="高热度（>198）"),LOG(游戏总表!I80,10),"") | AB80: =IF(AND(游戏总表!I80>0,游戏总表!Q80="低热度（≤198）"),LOG(游戏总表!I80,10),"") -> 3.7218106 | AC80: =IF(AND(游戏总表!I80>0,游戏总表!R80="全年龄"),LOG(游戏总表!I80,10),"") | AD80: =IF(AND(游戏总表!I80>0,游戏总表!R80="非全年龄"),LOG(游戏总表!I80,10),"") -> 3.7218106
Y81: =游戏总表!F81 -> 77.08 | Z81: =IF(游戏总表!I81>0,LOG(游戏总表!I81,10),"") -> 4.6481355 | AA81: =IF(AND(游戏总表!I81>0,游戏总表!Q81="高热度（>198）"),LOG(游戏总表!I81,10),"") -> 4.6481355 | AB81: =IF(AND(游戏总表!I81>0,游戏总表!Q81="低热度（≤198）"),LOG(游戏总表!I81,10),"") | AC81: =IF(AND(游戏总表!I81>0,游戏总表!R81="全年龄"),LOG(游戏总表!I81,10),"") -> 4.6481355 | AD81: =IF(AND(游戏总表!I81>0,游戏总表!R81="非全年龄"),LOG(游戏总表!I81,10),"")
Y82: =游戏总表!F82 -> 76.98 | Z82: =IF(游戏总表!I82>0,LOG(游戏总表!I82,10),"") -> 3.2345173 | AA82: =IF(AND(游戏总表!I82>0,游戏总表!Q82="高热度（>198）"),LOG(游戏总表!I82,10),"") | AB82: =IF(AND(游戏总表!I82>0,游戏总表!Q82="低热度（≤198）"),LOG(游戏总表!I82,10),"") -> 3.2345173 | AC82: =IF(AND(游戏总表!I82>0,游戏总表!R82="全年龄"),LOG(游戏总表!I82,10),"") -> 3.2345173 | AD82: =IF(AND(游戏总表!I82>0,游戏总表!R82="非全年龄"),LOG(游戏总表!I82,10),"")
Y83: =游戏总表!F83 -> 76.98 | Z83: =IF(游戏总表!I83>0,LOG(游戏总表!I83,10),"") -> 3.0802656 | AA83: =IF(AND(游戏总表!I83>0,游戏总表!Q83="高热度（>198）"),LOG(游戏总表!I83,10),"") | AB83: =IF(AND(游戏总表!I83>0,游戏总表!Q83="低热度（≤198）"),LOG(游戏总表!I83,10),"") -> 3.0802656 | AC83: =IF(AND(游戏总表!I83>0,游戏总表!R83="全年龄"),LOG(游戏总表!I83,10),"") -> 3.0802656 | AD83: =IF(AND(游戏总表!I83>0,游戏总表!R83="非全年龄"),LOG(游戏总表!I83,10),"")
Y84: =游戏总表!F84 -> 76.91 | Z84: =IF(游戏总表!I84>0,LOG(游戏总表!I84,10),"") -> 2.5550944 | AA84: =IF(AND(游戏总表!I84>0,游戏总表!Q84="高热度（>198）"),LOG(游戏总表!I84,10),"") | AB84: =IF(AND(游戏总表!I84>0,游戏总表!Q84="低热度（≤198）"),LOG(游戏总表!I84,10),"") -> 2.5550944 | AC84: =IF(AND(游戏总表!I84>0,游戏总表!R84="全年龄"),LOG(游戏总表!I84,10),"") -> 2.5550944 | AD84: =IF(AND(游戏总表!I84>0,游戏总表!R84="非全年龄"),LOG(游戏总表!I84,10),"")
Y85: =游戏总表!F85 -> 76.88 | Z85: =IF(游戏总表!I85>0,LOG(游戏总表!I85,10),"") -> 3.0366289 | AA85: =IF(AND(游戏总表!I85>0,游戏总表!Q85="高热度（>198）"),LOG(游戏总表!I85,10),"") | AB85: =IF(AND(游戏总表!I85>0,游戏总表!Q85="低热度（≤198）"),LOG(游戏总表!I85,10),"") -> 3.0366289 | AC85: =IF(AND(游戏总表!I85>0,游戏总表!R85="全年龄"),LOG(游戏总表!I85,10),"") | AD85: =IF(AND(游戏总表!I85>0,游戏总表!R85="非全年龄"),LOG(游戏总表!I85,10),"") -> 3.0366289
... Y4661: =游戏总表!F4661 -> 7.23 | Z4661: =IF(游戏总表!I4661>0,LOG(游戏总表!I4661,10),"") -> 2.3617278 | AA4661: =IF(AND(游戏总表!I4661>0,游戏总表!Q4661="高热度（>198）"),LOG(游戏总表!I4661,10),"") | AB4661: =IF(AND(游戏总表!I4661>0,游戏总表!Q4661="低热度（≤198）"),LOG(游戏总表!I4661,10),"") -> 2.3617278 | AC4661: =IF(AND(游戏总表!I4661>0,游戏总表!R4661="全年龄"),LOG(游戏总表!I4661,10),"") -> 2.3617278 | AD4661: =IF(AND(游戏总表!I4661>0,游戏总表!R4661="非全年龄"),LOG(游戏总表!I4661,10),"")

Sheet 图1_整体月度
A1: 2020–2025 视觉小说月度发行趋势（扩展口径） | S1: 月份 | T1: 全部游戏
S2: =月度统计!A2 -> 2020-01 | T2: =月度统计!B2 -> 28
S3: =月度统计!A3 -> 2020-02 | T3: =月度统计!B3 -> 46
S4: =月度统计!A4 -> 2020-03 | T4: =月度统计!B4 -> 31
S5: =月度统计!A5 -> 2020-04 | T5: =月度统计!B5 -> 46
S6: =月度统计!A6 -> 2020-05 | T6: =月度统计!B6 -> 37
S7: =月度统计!A7 -> 2020-06 | T7: =月度统计!B7 -> 44
S8: =月度统计!A8 -> 2020-07 | T8: =月度统计!B8 -> 50
S9: =月度统计!A9 -> 2020-08 | T9: =月度统计!B9 -> 40
S10: =月度统计!A10 -> 2020-09 | T10: =月度统计!B10 -> 34
S11: =月度统计!A11 -> 2020-10 | T11: =月度统计!B11 -> 53
S12: =月度统计!A12 -> 2020-11 | T12: =月度统计!B12 -> 44
S13: =月度统计!A13 -> 2020-12 | T13: =月度统计!B13 -> 45
... S24: =月度统计!A24 -> 2021-11 | T24: =月度统计!B24 -> 58
A25: 共 4,660 款；月份按 Steam 对应发行日归组。柱状与折线展示同一计数，便于同时观察规模和趋势。 | S25: =月度统计!A25 -> 2021-12 | T25: =月度统计!B25 -> 63
S26: =月度统计!A26 -> 2022-01 | T26: =月度统计!B26 -> 59
S27: =月度统计!A27 -> 2022-02 | T27: =月度统计!B27 -> 57
S28: =月度统计!A28 -> 2022-03 | T28: =月度统计!B28 -> 79
S29: =月度统计!A29 -> 2022-04 | T29: =月度统计!B29 -> 56
S30: =月度统计!A30 -> 2022-05 | T30: =月度统计!B30 -> 48
S31: =月度统计!A31 -> 2022-06 | T31: =月度统计!B31 -> 45
S32: =月度统计!A32 -> 2022-07 | T32: =月度统计!B32 -> 60
S33: =月度统计!A33 -> 2022-08 | T33: =月度统计!B33 -> 65
S34: =月度统计!A34 -> 2022-09 | T34: =月度统计!B34 -> 66
S35: =月度统计!A35 -> 2022-10 | T35: =月度统计!B35 -> 73
S36: =月度统计!A36 -> 2022-11 | T36: =月度统计!B36 -> 64
S37: =月度统计!A37 -> 2022-12 | T37: =月度统计!B37 -> 86
... S73: =月度统计!A73 -> 2025-12 | T73: =月度统计!B73 -> 94

Sheet 图2_整体年度
A1: 2020–2025 视觉小说年度发行趋势（扩展口径） | S1: 年份 | T1: 全部游戏
S2: =年度统计!A2 -> 2020 | T2: =年度统计!B2 -> 498
S3: =年度统计!A3 -> 2021 | T3: =年度统计!B3 -> 590
S4: =年度统计!A4 -> 2022 | T4: =年度统计!B4 -> 758
S5: =年度统计!A5 -> 2023 | T5: =年度统计!B5 -> 814
S6: =年度统计!A6 -> 2024 | T6: =年度统计!B6 -> 992
S7: =年度统计!A7 -> 2025 | T7: =年度统计!B7 -> 1008
A25: 年度汇总来自同一游戏总表；每个 Steam AppID 只计一次。

Sheet 图3_整体销量散点

Sheet 图4_热度月度
A1: 月度发行数量：评论数 >198 与 ≤198 | S1: 月份 | T1: 高热度（>198） | U1: 低热度（≤198）
S2: =月度统计!A2 -> 2020-01 | T2: =月度统计!C2 -> 8 | U2: =月度统计!D2 -> 20
S3: =月度统计!A3 -> 2020-02 | T3: =月度统计!C3 -> 15 | U3: =月度统计!D3 -> 31
S4: =月度统计!A4 -> 2020-03 | T4: =月度统计!C4 -> 9 | U4: =月度统计!D4 -> 22
S5: =月度统计!A5 -> 2020-04 | T5: =月度统计!C5 -> 14 | U5: =月度统计!D5 -> 32
S6: =月度统计!A6 -> 2020-05 | T6: =月度统计!C6 -> 11 | U6: =月度统计!D6 -> 26
S7: =月度统计!A7 -> 2020-06 | T7: =月度统计!C7 -> 9 | U7: =月度统计!D7 -> 35
S8: =月度统计!A8 -> 2020-07 | T8: =月度统计!C8 -> 16 | U8: =月度统计!D8 -> 34
S9: =月度统计!A9 -> 2020-08 | T9: =月度统计!C9 -> 12 | U9: =月度统计!D9 -> 28
S10: =月度统计!A10 -> 2020-09 | T10: =月度统计!C10 -> 8 | U10: =月度统计!D10 -> 26
S11: =月度统计!A11 -> 2020-10 | T11: =月度统计!C11 -> 17 | U11: =月度统计!D11 -> 36
S12: =月度统计!A12 -> 2020-11 | T12: =月度统计!C12 -> 10 | U12: =月度统计!D12 -> 34
S13: =月度统计!A13 -> 2020-12 | T13: =月度统计!C13 -> 13 | U13: =月度统计!D13 -> 32
... S24: =月度统计!A24 -> 2021-11 | T24: =月度统计!C24 -> 14 | U24: =月度统计!D24 -> 44
A25: 阈值 198 使评论数不超过阈值的游戏占 79.96%，约筛出热度最高的 20%。评论数来自 Steam 全语言、全部购买来源。 | S25: =月度统计!A25 -> 2021-12 | T25: =月度统计!C25 -> 15 | U25: =月度统计!D25 -> 48
S26: =月度统计!A26 -> 2022-01 | T26: =月度统计!C26 -> 12 | U26: =月度统计!D26 -> 47
S27: =月度统计!A27 -> 2022-02 | T27: =月度统计!C27 -> 11 | U27: =月度统计!D27 -> 46
S28: =月度统计!A28 -> 2022-03 | T28: =月度统计!C28 -> 19 | U28: =月度统计!D28 -> 60
S29: =月度统计!A29 -> 2022-04 | T29: =月度统计!C29 -> 12 | U29: =月度统计!D29 -> 44
S30: =月度统计!A30 -> 2022-05 | T30: =月度统计!C30 -> 8 | U30: =月度统计!D30 -> 40
S31: =月度统计!A31 -> 2022-06 | T31: =月度统计!C31 -> 8 | U31: =月度统计!D31 -> 37
S32: =月度统计!A32 -> 2022-07 | T32: =月度统计!C32 -> 14 | U32: =月度统计!D32 -> 46
S33: =月度统计!A33 -> 2022-08 | T33: =月度统计!C33 -> 16 | U33: =月度统计!D33 -> 49
S34: =月度统计!A34 -> 2022-09 | T34: =月度统计!C34 -> 13 | U34: =月度统计!D34 -> 53
S35: =月度统计!A35 -> 2022-10 | T35: =月度统计!C35 -> 15 | U35: =月度统计!D35 -> 58
S36: =月度统计!A36 -> 2022-11 | T36: =月度统计!C36 -> 6 | U36: =月度统计!D36 -> 58
S37: =月度统计!A37 -> 2022-12 | T37: =月度统计!C37 -> 9 | U37: =月度统计!D37 -> 77
... S73: =月度统计!A73 -> 2025-12 | T73: =月度统计!C73 -> 9 | U73: =月度统计!D73 -> 85

Sheet 图5_热度年度
A1: 年度发行数量：评论数 >198 与 ≤198 | S1: 年份 | T1: 高热度（>198） | U1: 低热度（≤198）
S2: =年度统计!A2 -> 2020 | T2: =年度统计!C2 -> 142 | U2: =年度统计!D2 -> 356
S3: =年度统计!A3 -> 2021 | T3: =年度统计!C3 -> 152 | U3: =年度统计!D3 -> 438
S4: =年度统计!A4 -> 2022 | T4: =年度统计!C4 -> 143 | U4: =年度统计!D4 -> 615
S5: =年度统计!A5 -> 2023 | T5: =年度统计!C5 -> 143 | U5: =年度统计!D5 -> 671
S6: =年度统计!A6 -> 2024 | T6: =年度统计!C6 -> 192 | U6: =年度统计!D6 -> 800
S7: =年度统计!A7 -> 2025 | T7: =年度统计!C7 -> 162 | U7: =年度统计!D7 -> 846
A25: 高热度：Steam 评论数 >198；低热度：Steam 评论数 ≤198。

Sheet 图6_热度销量散点

Sheet 图7_年龄月度
A1: 月度发行数量：全年龄与非全年龄（按 has_ero） | S1: 月份 | T1: 全年龄 | U1: 非全年龄
S2: =月度统计!A2 -> 2020-01 | T2: =月度统计!F2 -> 23 | U2: =月度统计!G2 -> 5
S3: =月度统计!A3 -> 2020-02 | T3: =月度统计!F3 -> 36 | U3: =月度统计!G3 -> 10
S4: =月度统计!A4 -> 2020-03 | T4: =月度统计!F4 -> 24 | U4: =月度统计!G4 -> 7
S5: =月度统计!A5 -> 2020-04 | T5: =月度统计!F5 -> 37 | U5: =月度统计!G5 -> 9
S6: =月度统计!A6 -> 2020-05 | T6: =月度统计!F6 -> 29 | U6: =月度统计!G6 -> 8
S7: =月度统计!A7 -> 2020-06 | T7: =月度统计!F7 -> 40 | U7: =月度统计!G7 -> 4
S8: =月度统计!A8 -> 2020-07 | T8: =月度统计!F8 -> 41 | U8: =月度统计!G8 -> 9
S9: =月度统计!A9 -> 2020-08 | T9: =月度统计!F9 -> 31 | U9: =月度统计!G9 -> 9
S10: =月度统计!A10 -> 2020-09 | T10: =月度统计!F10 -> 28 | U10: =月度统计!G10 -> 6
S11: =月度统计!A11 -> 2020-10 | T11: =月度统计!F11 -> 44 | U11: =月度统计!G11 -> 9
S12: =月度统计!A12 -> 2020-11 | T12: =月度统计!F12 -> 39 | U12: =月度统计!G12 -> 5
S13: =月度统计!A13 -> 2020-12 | T13: =月度统计!F13 -> 33 | U13: =月度统计!G13 -> 12
... S24: =月度统计!A24 -> 2021-11 | T24: =月度统计!F24 -> 42 | U24: =月度统计!G24 -> 16
A25: 任一关联 VNDB Release 的 has_ero=true 即归为非全年龄；否则已知 has_ero=false 归为全年龄。minage 不参与判断。 | S25: =月度统计!A25 -> 2021-12 | T25: =月度统计!F25 -> 44 | U25: =月度统计!G25 -> 19
S26: =月度统计!A26 -> 2022-01 | T26: =月度统计!F26 -> 44 | U26: =月度统计!G26 -> 15
S27: =月度统计!A27 -> 2022-02 | T27: =月度统计!F27 -> 40 | U27: =月度统计!G27 -> 17
S28: =月度统计!A28 -> 2022-03 | T28: =月度统计!F28 -> 49 | U28: =月度统计!G28 -> 30
S29: =月度统计!A29 -> 2022-04 | T29: =月度统计!F29 -> 26 | U29: =月度统计!G29 -> 30
S30: =月度统计!A30 -> 2022-05 | T30: =月度统计!F30 -> 31 | U30: =月度统计!G30 -> 17
S31: =月度统计!A31 -> 2022-06 | T31: =月度统计!F31 -> 28 | U31: =月度统计!G31 -> 17
S32: =月度统计!A32 -> 2022-07 | T32: =月度统计!F32 -> 43 | U32: =月度统计!G32 -> 17
S33: =月度统计!A33 -> 2022-08 | T33: =月度统计!F33 -> 50 | U33: =月度统计!G33 -> 15
S34: =月度统计!A34 -> 2022-09 | T34: =月度统计!F34 -> 40 | U34: =月度统计!G34 -> 26
S35: =月度统计!A35 -> 2022-10 | T35: =月度统计!F35 -> 51 | U35: =月度统计!G35 -> 22
S36: =月度统计!A36 -> 2022-11 | T36: =月度统计!F36 -> 42 | U36: =月度统计!G36 -> 22
S37: =月度统计!A37 -> 2022-12 | T37: =月度统计!F37 -> 51 | U37: =月度统计!G37 -> 35
... S73: =月度统计!A73 -> 2025-12 | T73: =月度统计!F73 -> 71 | U73: =月度统计!G73 -> 23

Sheet 图8_年龄年度
A1: 年度发行数量：全年龄与非全年龄（按 has_ero） | S1: 年份 | T1: 全年龄 | U1: 非全年龄
S2: =年度统计!A2 -> 2020 | T2: =年度统计!F2 -> 405 | U2: =年度统计!G2 -> 93
S3: =年度统计!A3 -> 2021 | T3: =年度统计!F3 -> 432 | U3: =年度统计!G3 -> 158
S4: =年度统计!A4 -> 2022 | T4: =年度统计!F4 -> 495 | U4: =年度统计!G4 -> 263
S5: =年度统计!A5 -> 2023 | T5: =年度统计!F5 -> 559 | U5: =年度统计!G5 -> 255
S6: =年度统计!A6 -> 2024 | T6: =年度统计!F6 -> 705 | U6: =年度统计!G6 -> 287
S7: =年度统计!A7 -> 2025 | T7: =年度统计!F7 -> 740 | U7: =年度统计!G7 -> 268
A25: 分类直接依据 VNDB Release.has_ero；本次样本没有 has_ero 未知项。

Sheet 图9_年龄销量散点

Sheet 图10_年龄占比
A1: 全年龄与非全年龄游戏占比（按 VNDB Release.has_ero） | S1: 分类 | T1: 游戏数
S2: 全年龄 | T2: =COUNTIF(游戏总表!$R$2:$R$4661,AF2) -> 0
S3: 非全年龄 | T3: =COUNTIF(游戏总表!$R$2:$R$4661,AF3) -> 0
S4: 未知 | T4: =COUNTIF(游戏总表!$R$2:$R$4661,AF4) -> 0
L5: 分类明细
L6: 分类 | M6: 游戏数 | N6: 占比
L7: 全年龄 | M7: =图表数据!AG2 -> 3336 | N7: =M7/SUM($M$7:$M$9) -> 0.71587983
L8: 非全年龄 | M8: =图表数据!AG3 -> 1324 | N8: =M8/SUM($M$7:$M$9) -> 0.28412017
L9: 未知 | M9: =图表数据!AG4 -> 0 | N9: =M9/SUM($M$7:$M$9) -> 0
A25: 非全年龄：任一关联 Release 的 has_ero=true；全年龄：无 true 且至少一个 has_ero=false。
